<mujoco model="ur5_gripah">
    <body name="base_link" pos="0 0 1.0">
        <inertial pos="0 0 0" quat="0.5 0.5 -0.5 0.5" mass="4" diaginertia="0.0072 0.00443333 0.00443333" />
        <geom type="mesh" rgba="0.7 0.7 0.7 1" mesh="base" />
        <body name="shoulder_link" pos="0 0 0.089159">
            <inertial pos="0 0 0" mass="3.7" diaginertia="0.0102675 0.0102675 0.00666" />
            <joint name="shoulder_pan_joint" pos="0 0 0" axis="0 0 1" limited="true" range="-3.14159 3.14159" />
            <geom type="mesh" rgba="0.7 0.7 0.7 1" mesh="shoulder" />
            <body name="upper_arm_link" pos="0 0.13585 0" quat="0.707107 0 0.707107 0">
                <inertial pos="0 0 0.28" mass="8.393" diaginertia="0.226891 0.226891 0.0151074" />
                <joint name="shoulder_lift_joint" pos="0 0 0" axis="0 1 0" limited="true" range="-3.14159 3.14159" />
                <geom type="mesh" rgba="0.7 0.7 0.7 1" mesh="upperarm" />
                <body name="forearm_link" pos="0 -0.1197 0.425">
                    <inertial pos="0 0 0.25" mass="2.275" diaginertia="0.0494433 0.0494433 0.004095" />
                    <joint name="elbow_joint" pos="0 0 0" axis="0 1 0" limited="true" range="-3.14159 3.14159" />
                    <geom type="mesh" rgba="0.7 0.7 0.7 1" mesh="forearm" />
                    <body name="wrist_1_link" pos="0 0 0.39225" quat="0.707107 0 0.707107 0">
                        <inertial pos="0 0 0" quat="0.5 0.5 -0.5 0.5" mass="1.219" diaginertia="0.21942 0.111173 0.111173" />
                        <joint name="wrist_1_joint" pos="0 0 0" axis="0 1 0" limited="true" range="-3.14159 3.14159" />
                        <geom type="mesh" rgba="0.7 0.7 0.7 1" mesh="wrist1" />
                        <body name="wrist_2_link" pos="0 0.093 0">
                            <inertial pos="0 0 0" quat="0.5 0.5 -0.5 0.5" mass="1.219" diaginertia="0.21942 0.111173 0.111173" />
                            <joint name="wrist_2_joint" pos="0 0 0" axis="0 0 1" limited="true" range="-3.14159 3.14159" />
                            <geom type="mesh" rgba="0.7 0.7 0.7 1" mesh="wrist2" />
                            <body name="wrist_3_link" pos="0 0 0.09465">
                                <inertial pos="0 0 0" quat="0.5 0.5 -0.5 0.5" mass="0.1879" diaginertia="0.033822 0.0171365 0.0171365" />
                                <joint name="wrist_3_joint" pos="0 0 0" axis="0 1 0" limited="true" range="-3.14159 3.14159" />
                                <geom type="mesh" rgba="0.7 0.7 0.7 1" mesh="wrist3" />
                                <body name="ee_link" pos="0 0.0823 0" quat="0.707107 0 0 0.707107">
                                    <inertial pos="-0.01 0 0" mass="0.001" diaginertia="1.66667e-08 1.66667e-08 1.66667e-08" />
                                    <geom size="0.005 0.005 0.005" pos="-0.01 0 0" type="box" />
                                </body>
                                <body name="tool0" pos="0 0.0823 0" quat="0.707107 -0.707107 0 0">
                                    <inertial pos="0 0.0823 0" quat="0.707107 -0.707107 0 0" mass="0" diaginertia="0 0 0" />
                                    <body name="gripah_base" pos="0 0 0.02" quat="0.707107 0.707107 0 0">
                                        <site name="finger_center" pos="0.19 0 0" size="0.005" rgba=".1 .9 0 .8" type="sphere"/>
                                        <inertial pos="-0.020421 0 0" mass="0.18" diaginertia="1 1 1" />
                                        <geom type="mesh" rgba="0.89804 0.91765 0.92941 1" mesh="wrist" />
                                        <body name="wide_finger_link" pos="0.055 0 0" quat="0.70709 0.707092 0.00471388 -0.0047139">
                                            <inertial pos="0.056976 0.015337 -2.3122e-09" quat="0.653281 0.653281 -0.270598 -0.270598" mass="0.0167" diaginertia="1.01 1 0.99" />
                                            <joint name="wide_finger_joint" pos="0 0 0" axis="0 0 1" limited="true" range="-1.0472 1.0472" damping="10"/>
                                            <geom type="mesh" rgba="0.89804 0.91765 0.92941 1" mesh="wide_finger" />
                                        </body>
                                        <body name="narrow_finger_link" pos="0.055 0 0" quat="0.70709 0.707092 0.00471388 -0.0047139">
                                            <inertial pos="0.052556 0.013896 2.3305e-07" quat="0.653281 0.653281 -0.270598 -0.270598" mass="0.016641" diaginertia="1.03 1 0.97" />
                                            <joint name="narrow_finger_joint" pos="0 0 0" axis="0 0 -1" limited="true" range="-1.0472 1.0472" damping="10"/>
                                            <geom type="mesh" rgba="0.89804 0.91765 0.92941 1" mesh="narrow_finger" />
                                        </body>
                                    </body>
                                </body>
                            </body>
                        </body>
                    </body>
                </body>
            </body>
        </body>
    </body>
</mujoco>
